<?xml version="1.0" ?>
<robot name="turtlebot3_waffle_1d" xmlns:xacro="http://ros.org/wiki/xacro">

  <xacro:include filename="caster.xacro"/>
  <xacro:include filename="dt35.xacro"/>
  <xacro:include filename="imu.xacro"/>

  <link name="base_footprint"/>

  <joint name="base_joint" type="fixed">
    <parent link="base_footprint"/>
    <child link="base_link" />
    <origin xyz="0 0 0.010" rpy="0 0 0"/>
  </joint>

  <!-- Links and Joints -->
  <link name="base_link">
    <visual>
      <origin xyz="-0.064 0 0.047" rpy="0 0 0"/>
      <geometry>
        <box size="0.266 0.266 0.094"/>
      </geometry>
    </visual>
    <collision>
      <origin xyz="-0.064 0 0.047" rpy="0 0 0"/>
      <geometry>
        <box size="0.266 0.266 0.094"/>
      </geometry>
    </collision>
    <inertial>
      <origin xyz="0 0 0" rpy="0 0 0"/>
      <mass value="3.0"/>
      <inertia ixx="8.7002718e-03" ixy="-4.7576583e-05" ixz="1.1160499e-04"
                iyy="8.6195418e-03" iyz="-3.5422299e-06" izz="1.4612727e-02" />
    </inertial>
  </link>

  <!-- Wheel Template -->
  <xacro:macro name="wheel_link" params="name x y z">
    <joint name="${name}_joint" type="continuous">
      <parent link="base_link"/>
      <child link="${name}_link"/>
      <origin xyz="${x} ${y} ${z}" rpy="-1.57 0 0"/>
      <axis xyz="0 0 1"/>
    </joint>
    <link name="${name}_link">
      <visual>
        <origin xyz="0 0 0" rpy="0 0 0"/>
        <geometry>
          <cylinder length="0.018" radius="0.033"/>
        </geometry>
      </visual>
      <collision>
        <origin xyz="0 0 0" rpy="0 0 0"/>
        <geometry>
          <cylinder length="0.018" radius="0.033"/>
        </geometry>
      </collision>
      <inertial>
        <origin xyz="0 0 0" />
        <mass value="0.02849894" />
        <inertia ixx="1.1175580e-05" ixy="0" ixz="0"
                 iyy="1.1192413e-05" iyz="0" izz="2.0712558e-05" />
      </inertial>
    </link>
  </xacro:macro>

  <!-- Base Structure -->
  <xacro:wheel_link name="wheel_left" x="0.0" y="0.144" z="0.023" />
  <xacro:wheel_link name="wheel_right" x="0.0" y="-0.144" z="0.023" />
  <xacro:caster_macro name="caster_back_right" x="-0.177" y="-0.064" z="-0.004"/>
  <xacro:caster_macro name="caster_back_left" x="-0.177" y="0.064" z="-0.004"/>
  <xacro:imu_macro name="tb3_imu" parent="base_link" xyz="0.0 0 0.068" />

  <xacro:dt35_macro name="front_laser" parent="base_link" x="0.069" y="0" yaw="0" />
  <xacro:dt35_macro name="lf_laser" parent="base_link" x="0.069" y="0.133" yaw="45" />
  <xacro:dt35_macro name="l_laser" parent="base_link" x="0.0" y="0.133" yaw="90" />
  <xacro:dt35_macro name="lb_laser" parent="base_link" x="-0.197" y="0.133" yaw="135" />
  <xacro:dt35_macro name="rf_laser" parent="base_link" x="0.069" y="-0.133" yaw="-45" />
  <xacro:dt35_macro name="r_laser" parent="base_link" x="0.0" y="-0.133" yaw="-90" />
  <xacro:dt35_macro name="rb_laser" parent="base_link" x="-0.197" y="-0.133" yaw="-135" />
  <xacro:dt35_macro name="back_laser" parent="base_link" x="-0.197" y="0" yaw="180" />

  <gazebo>
    <plugin name="turtlebot3_diff_drive" filename="libgazebo_ros_diff_drive.so">
      <ros>
      </ros>

      <update_rate>30</update_rate>

      <!-- wheels -->
      <left_joint>wheel_left_joint</left_joint>
      <right_joint>wheel_right_joint</right_joint>

      <!-- kinematics -->
      <wheel_separation>0.287</wheel_separation>
      <wheel_diameter>0.066</wheel_diameter>

      <!-- limits -->
      <max_wheel_torque>20</max_wheel_torque>
      <max_wheel_acceleration>1.0</max_wheel_acceleration>

      <command_topic>cmd_vel</command_topic>

      <!-- output -->
      <publish_odom>true</publish_odom>
      <publish_odom_tf>false</publish_odom_tf>
      <publish_wheel_tf>false</publish_wheel_tf>

      <odometry_topic>odom</odometry_topic>
      <odometry_frame>map</odometry_frame>
      <robot_base_frame>base_footprint</robot_base_frame>

    </plugin>
  </gazebo>

  <gazebo>
    <plugin name="gazebo_ros_p3d" filename="libgazebo_ros_p3d.so">
      <ros>
        <remapping>odom:=gazebo_position</remapping>
      </ros>
      <body_name>base_footprint</body_name>
      <frame_name>map</frame_name>
      <update_rate>30</update_rate>
      <xyz_offset>0 0 0</xyz_offset>
      <rpy_offset>0 0 0</rpy_offset>
      <gaussian_noise>0.0</gaussian_noise>
    </plugin>
  </gazebo>
</robot>
